Workbook

Sheet SignalWatchlist
A1: SignalID | B1: SignalName | C1: SignalType | D1: ExpectedWindow | E1: Owner | F1: ExpectedDirection | G1: EstimatedImpact | H1: EvidenceSource | I1: Status | J1: Notes
A2: SIG-021 | B2: ATS guideline update discussion | C2: Regulatory | D2: ATS meeting | E2: Medical Affairs | F2: + | G2: High | H2: ATS conference | I2: Pending | J2: Guideline panel discussion expected
A3: SIG-022 | B3: Payer coverage expansion | C3: Commercial | D3: Next 6 months | E3: Market Access | F3: + | G3: Medium | H3: Payer policy updates | I3: Pending | J3: Monitoring policy bulletins
A4: SIG-023 | B4: Confirmatory trial interim data | C4: Clinical | D4: Q4 | E4: Clinical Team | F4: + | G4: High | H4: ClinicalTrials.gov | I4: Pending | J4: Interim analysis expected

Sheet ChangeLog
A1: Date | B1: SignalID | C1: SignalDescription | D1: Direction | E1: ProbabilityChange | F1: Interpretation | G1: Analyst
A2: 2026-05-12 | B2: SIG-010 | C2: ENCORE fatigue endpoint miss | D2: Negative | E2: -0.03 | F2: Minor reduction in adoption confidence | G2: Analyst
A3: 2026-06-03 | B3: SIG-014 | C3: Positive ATS panel commentary | D3: Positive | E3: 0.05 | F3: Improves guideline adoption probability | G3: Analyst
A4: 2026-03-15 | B4: V18 | C4: Inserted actor-reaction layer between signal structuring and probability engine. | D4: Preserved original V17 cockpit sheets; added CaseHeader, SignalRegister, Actors, ActorReactionMatrix, ActorAggregation, ProbabilityEngine, InterpretationLayer, and CalibrationLog.

Sheet WeeklyBrief
A1: CaseID | B1: CurrentProbability | C1: ChangeSinceLastReview | D1: TopDriver1 | E1: TopDriver2 | F1: TopDriver3 | G1: SignalsToMonitor | H1: NextDecisionCheckpoint | I1: PreparedBy | J1: Date
A2: ARK_FL_001 | B2: 0.42 | C2: +0.03 | D2: Guideline adoption probability | E2: Confirmatory clinical evidence | F2: Payer coverage expansion | G2: ATS guideline panel discussion | H2: ATS Annual Meeting | I2: CIOS Engine | J2: Auto-generated

Sheet FieldIntelligenceInbox
A1: FeedbackID | B1: Date | C1: Brand | D1: AudienceType | E1: Specialty | F1: Subspecialty | G1: Region | H1: SourceRole | I1: SourceName | J1: SignalCategory | K1: ObservedBarrier | L1: RawFieldFeedback | M1: BeliefShiftRisk | N1: MessageMismatchRisk | O1: AccessRisk | P1: CompetitiveRisk | Q1: UrgencyScore_1to5 | R1: CredibilityScore_1to5 | S1: FrequencyScore_1to5 | T1: PotentialImpact_1to5 | U1: TotalSignalScore | V1: CIOSSignalDirection | W1: SuggestedRoute | X1: PrimaryTargetPopulation | Y1: MIOSMessagePriority | Z1: OHOSObjectionPriority | AA1: FieldActionNeeded | AB1: Notes
A2: FB-001 | B2: 2026-03-13 | C2: ARIKAYCE | D2: HCP | E2: Pulmonology | F2: NTM-focused | G2: US South | H2: MSL | I2: Example KOL | J2: Clinical perception | K2: Culture conversion seen as less persuasive than symptom improvement | L2: Pulmonologists are asking for a more direct connection between microbiology and fatigue / functioning. | M2: 4 | N2: 5 | O2: 1 | P2: 1 | Q2: 5 | R2: 4 | S2: 3 | T2: 5 | U2: =SUM(Q2:T2) -> 17 | V2: Negative | W2: CIOS→MIOS+OHOS | X2: Pulmonology / community | Y2: High | Z2: High | AA2: Yes | AB2: Use symptom-bridge framing
A3: FB-002 | B3: 2026-03-13 | C3: ARIKAYCE | D3: HCP | E3: Infectious Disease | F3: Academic ID | G3: Northeast | H3: Sales | I3: Top account | J3: Competitive message | K3: Competitor perceived as easier to position because mechanism is simpler | L3: ID specialists are still persuaded by microbiology but want cleaner differentiation vs alternatives. | M3: 2 | N3: 3 | O3: 1 | P3: 4 | Q3: 3 | R3: 3 | S3: 2 | T3: 4 | U3: =SUM(Q3:T3) -> 12 | V3: Negative | W3: CIOS→OHOS | X3: Infectious Disease / academic | Y3: Medium | Z3: High | AA3: Yes | AB3: Differentiate on evidence depth
A4: FB-003 | B4: 2026-03-13 | C4: ARIKAYCE | D4: HCP | E4: Pulmonology | F4: General Pulm | G4: Midwest | H4: Sales | I4: Community account | J4: Access / workflow | K4: Diagnosis and referral pathway slowing consideration | L4: General pulmonologists need a simpler patient-identification story and referral confidence. | M4: 3 | N4: 4 | O4: 4 | P4: 1 | Q4: 4 | R4: 3 | S4: 4 | T4: 4 | U4: =SUM(Q4:T4) -> 15 | V4: Negative | W4: CIOS→MIOS | X4: Pulmonology / general | Y4: High | Z4: Medium | AA4: Yes | AB4: Simplify candidate-ID narrative

Sheet SegmentMessagingMatrix
A1: SegmentID | B1: AudienceType | C1: Specialty | D1: Subspecialty | E1: DecisionDriver1 | F1: DecisionDriver2 | G1: PreferredEvidenceType | H1: MessageEmphasis | I1: ProofNeed | J1: LikelyObjectionTheme | K1: OHOSResponseStyle | L1: FieldChannel | M1: PriorityRank
A2: SEG-001 | B2: HCP | C2: Pulmonology | D2: General Pulm | E2: Symptoms / function | F2: Simple patient identification | G2: Clinical outcomes + practical framing | H2: Symptom bridge + candidate identification | I2: Real-world practicality | J2: Referral complexity / unclear patient fit | K2: Simple, mechanism-to-practice | L2: Sales + MSL | M2: 1
A3: SEG-002 | B3: HCP | C3: Pulmonology | D3: NTM-focused | E3: Disease control | F3: Evidence depth | G3: Microbiology + clinical linkage | H3: Disease control → symptom/function | I3: Scientific linkage | J3: Need proof that endpoint matters clinically | K3: Evidence bridge with mechanistic logic | L3: MSL-led | M3: 2
A4: SEG-003 | B4: HCP | C4: Infectious Disease | D4: Academic ID | E4: Microbiology | F4: Differentiation | G4: Comparative evidence depth | H4: Evidence hierarchy + differentiation | I4: Study design rigor | J4: Alternative options easier to explain | K4: Structured objection ladder | L4: MSL-led | M4: 3

Sheet MessageUpdateRouter
A1: Field Intelligence Routing Engine
A3: FeedbackID | B3: TotalSignalScore | C3: SuggestedRoute | D3: PrimaryTargetPopulation | E3: MIOSMessagePriority | F3: OHOSObjectionPriority | G3: EscalationLevel | H3: RecommendedOwner | I3: RecommendedOutput | J3: FieldTeam
A4: =FieldIntelligenceInbox!A2 -> FB-001 | B4: =FieldIntelligenceInbox!U2 -> 17 | C4: =IF(B4="","",FieldIntelligenceInbox!W2) -> CIOS→MIOS+OHOS | D4: =IF(B4="","",FieldIntelligenceInbox!X2) -> Pulmonology / community | E4: =IF(B4="","",FieldIntelligenceInbox!Y2) -> High | F4: =IF(B4="","",FieldIntelligenceInbox!Z2) -> High | G4: =IF(B4="","",IF(B4>=16,"Urgent",IF(B4>=12,"High","Standard"))) -> Urgent | H4: =IF(B4="","",IF(C4="CIOS→MIOS+OHOS","Brand Strategy + Medical + Training",IF(C4="CIOS→MIOS","Medical Strategy",IF(C4="CIOS→OHOS","Field Strategy / Training","CIOS Review")))) -> Brand Strategy + Medical + Training | I4: =IF(B4="","",IF(C4="CIOS→MIOS+OHOS","Update core message + objection module + segment guidance",IF(C4="CIOS→MIOS","Update message architecture + segment narrative",IF(C4="CIOS→OHOS","Update objection ladder + response card","Review")))) -> Update core message + objection module + segment guidance | J4: =IF(B4="","",IF(LEFT(D4,11)="Pulmonology","Sales + MSL","MSL-led")) -> Sales + MSL
A5: =FieldIntelligenceInbox!A3 -> FB-002 | B5: =FieldIntelligenceInbox!U3 -> 12 | C5: =IF(B5="","",FieldIntelligenceInbox!W3) -> CIOS→OHOS | D5: =IF(B5="","",FieldIntelligenceInbox!X3) -> Infectious Disease / academic | E5: =IF(B5="","",FieldIntelligenceInbox!Y3) -> Medium | F5: =IF(B5="","",FieldIntelligenceInbox!Z3) -> High | G5: =IF(B5="","",IF(B5>=16,"Urgent",IF(B5>=12,"High","Standard"))) -> High | H5: =IF(B5="","",IF(C5="CIOS→MIOS+OHOS","Brand Strategy + Medical + Training",IF(C5="CIOS→MIOS","Medical Strategy",IF(C5="CIOS→OHOS","Field Strategy / Training","CIOS Review")))) -> Field Strategy / Training | I5: =IF(B5="","",IF(C5="CIOS→MIOS+OHOS","Update core message + objection module + segment guidance",IF(C5="CIOS→MIOS","Update message architecture + segment narrative",IF(C5="CIOS→OHOS","Update objection ladder + response card","Review")))) -> Update objection ladder + response card | J5: =IF(B5="","",IF(LEFT(D5,11)="Pulmonology","Sales + MSL","MSL-led")) -> MSL-led
A6: =FieldIntelligenceInbox!A4 -> FB-003 | B6: =FieldIntelligenceInbox!U4 -> 15 | C6: =IF(B6="","",FieldIntelligenceInbox!W4) -> CIOS→MIOS | D6: =IF(B6="","",FieldIntelligenceInbox!X4) -> Pulmonology / general | E6: =IF(B6="","",FieldIntelligenceInbox!Y4) -> High | F6: =IF(B6="","",FieldIntelligenceInbox!Z4) -> Medium | G6: =IF(B6="","",IF(B6>=16,"Urgent",IF(B6>=12,"High","Standard"))) -> High | H6: =IF(B6="","",IF(C6="CIOS→MIOS+OHOS","Brand Strategy + Medical + Training",IF(C6="CIOS→MIOS","Medical Strategy",IF(C6="CIOS→OHOS","Field Strategy / Training","CIOS Review")))) -> Medical Strategy | I6: =IF(B6="","",IF(C6="CIOS→MIOS+OHOS","Update core message + objection module + segment guidance",IF(C6="CIOS→MIOS","Update message architecture + segment narrative",IF(C6="CIOS→OHOS","Update objection ladder + response card","Review")))) -> Update message architecture + segment narrative | J6: =IF(B6="","",IF(LEFT(D6,11)="Pulmonology","Sales + MSL","MSL-led")) -> Sales + MSL
A7: =FieldIntelligenceInbox!A5 -> 0 | B7: =FieldIntelligenceInbox!U5 -> 0 | C7: =IF(B7="","",FieldIntelligenceInbox!W5) | D7: =IF(B7="","",FieldIntelligenceInbox!X5) | E7: =IF(B7="","",FieldIntelligenceInbox!Y5) | F7: =IF(B7="","",FieldIntelligenceInbox!Z5) | G7: =IF(B7="","",IF(B7>=16,"Urgent",IF(B7>=12,"High","Standard"))) | H7: =IF(B7="","",IF(C7="CIOS→MIOS+OHOS","Brand Strategy + Medical + Training",IF(C7="CIOS→MIOS","Medical Strategy",IF(C7="CIOS→OHOS","Field Strategy / Training","CIOS Review")))) | I7: =IF(B7="","",IF(C7="CIOS→MIOS+OHOS","Update core message + objection module + segment guidance",IF(C7="CIOS→MIOS","Update message architecture + segment narrative",IF(C7="CIOS→OHOS","Update objection ladder + response card","Review")))) | J7: =IF(B7="","",IF(LEFT(D7,11)="Pulmonology","Sales + MSL","MSL-led"))
A8: =FieldIntelligenceInbox!A6 -> 0 | B8: =FieldIntelligenceInbox!U6 -> 0 | C8: =IF(B8="","",FieldIntelligenceInbox!W6) | D8: =IF(B8="","",FieldIntelligenceInbox!X6) | E8: =IF(B8="","",FieldIntelligenceInbox!Y6) | F8: =IF(B8="","",FieldIntelligenceInbox!Z6) | G8: =IF(B8="","",IF(B8>=16,"Urgent",IF(B8>=12,"High","Standard"))) | H8: =IF(B8="","",IF(C8="CIOS→MIOS+OHOS","Brand Strategy + Medical + Training",IF(C8="CIOS→MIOS","Medical Strategy",IF(C8="CIOS→OHOS","Field Strategy / Training","CIOS Review")))) | I8: =IF(B8="","",IF(C8="CIOS→MIOS+OHOS","Update core message + objection module + segment guidance",IF(C8="CIOS→MIOS","Update message architecture + segment narrative",IF(C8="CIOS→OHOS","Update objection ladder + response card","Review")))) | J8: =IF(B8="","",IF(LEFT(D8,11)="Pulmonology","Sales + MSL","MSL-led"))
A9: =FieldIntelligenceInbox!A7 -> 0 | B9: =FieldIntelligenceInbox!U7 -> 0 | C9: =IF(B9="","",FieldIntelligenceInbox!W7) | D9: =IF(B9="","",FieldIntelligenceInbox!X7) | E9: =IF(B9="","",FieldIntelligenceInbox!Y7) | F9: =IF(B9="","",FieldIntelligenceInbox!Z7) | G9: =IF(B9="","",IF(B9>=16,"Urgent",IF(B9>=12,"High","Standard"))) | H9: =IF(B9="","",IF(C9="CIOS→MIOS+OHOS","Brand Strategy + Medical + Training",IF(C9="CIOS→MIOS","Medical Strategy",IF(C9="CIOS→OHOS","Field Strategy / Training","CIOS Review")))) | I9: =IF(B9="","",IF(C9="CIOS→MIOS+OHOS","Update core message + objection module + segment guidance",IF(C9="CIOS→MIOS","Update message architecture + segment narrative",IF(C9="CIOS→OHOS","Update objection ladder + response card","Review")))) | J9: =IF(B9="","",IF(LEFT(D9,11)="Pulmonology","Sales + MSL","MSL-led"))
A10: =FieldIntelligenceInbox!A8 -> 0 | B10: =FieldIntelligenceInbox!U8 -> 0 | C10: =IF(B10="","",FieldIntelligenceInbox!W8) | D10: =IF(B10="","",FieldIntelligenceInbox!X8) | E10: =IF(B10="","",FieldIntelligenceInbox!Y8) | F10: =IF(B10="","",FieldIntelligenceInbox!Z8) | G10: =IF(B10="","",IF(B10>=16,"Urgent",IF(B10>=12,"High","Standard"))) | H10: =IF(B10="","",IF(C10="CIOS→MIOS+OHOS","Brand Strategy + Medical + Training",IF(C10="CIOS→MIOS","Medical Strategy",IF(C10="CIOS→OHOS","Field Strategy / Training","CIOS Review")))) | I10: =IF(B10="","",IF(C10="CIOS→MIOS+OHOS","Update core message + objection module + segment guidance",IF(C10="CIOS→MIOS","Update message architecture + segment narrative",IF(C10="CIOS→OHOS","Update objection ladder + response card","Review")))) | J10: =IF(B10="","",IF(LEFT(D10,11)="Pulmonology","Sales + MSL","MSL-led"))
A11: =FieldIntelligenceInbox!A9 -> 0 | B11: =FieldIntelligenceInbox!U9 -> 0 | C11: =IF(B11="","",FieldIntelligenceInbox!W9) | D11: =IF(B11="","",FieldIntelligenceInbox!X9) | E11: =IF(B11="","",FieldIntelligenceInbox!Y9) | F11: =IF(B11="","",FieldIntelligenceInbox!Z9) | G11: =IF(B11="","",IF(B11>=16,"Urgent",IF(B11>=12,"High","Standard"))) | H11: =IF(B11="","",IF(C11="CIOS→MIOS+OHOS","Brand Strategy + Medical + Training",IF(C11="CIOS→MIOS","Medical Strategy",IF(C11="CIOS→OHOS","Field Strategy / Training","CIOS Review")))) | I11: =IF(B11="","",IF(C11="CIOS→MIOS+OHOS","Update core message + objection module + segment guidance",IF(C11="CIOS→MIOS","Update message architecture + segment narrative",IF(C11="CIOS→OHOS","Update objection ladder + response card","Review")))) | J11: =IF(B11="","",IF(LEFT(D11,11)="Pulmonology","Sales + MSL","MSL-led"))
A12: =FieldIntelligenceInbox!A10 -> 0 | B12: =FieldIntelligenceInbox!U10 -> 0 | C12: =IF(B12="","",FieldIntelligenceInbox!W10) | D12: =IF(B12="","",FieldIntelligenceInbox!X10) | E12: =IF(B12="","",FieldIntelligenceInbox!Y10) | F12: =IF(B12="","",FieldIntelligenceInbox!Z10) | G12: =IF(B12="","",IF(B12>=16,"Urgent",IF(B12>=12,"High","Standard"))) | H12: =IF(B12="","",IF(C12="CIOS→MIOS+OHOS","Brand Strategy + Medical + Training",IF(C12="CIOS→MIOS","Medical Strategy",IF(C12="CIOS→OHOS","Field Strategy / Training","CIOS Review")))) | I12: =IF(B12="","",IF(C12="CIOS→MIOS+OHOS","Update core message + objection module + segment guidance",IF(C12="CIOS→MIOS","Update message architecture + segment narrative",IF(C12="CIOS→OHOS","Update objection ladder + response card","Review")))) | J12: =IF(B12="","",IF(LEFT(D12,11)="Pulmonology","Sales + MSL","MSL-led"))
A13: =FieldIntelligenceInbox!A11 -> 0 | B13: =FieldIntelligenceInbox!U11 -> 0 | C13: =IF(B13="","",FieldIntelligenceInbox!W11) | D13: =IF(B13="","",FieldIntelligenceInbox!X11) | E13: =IF(B13="","",FieldIntelligenceInbox!Y11) | F13: =IF(B13="","",FieldIntelligenceInbox!Z11) | G13: =IF(B13="","",IF(B13>=16,"Urgent",IF(B13>=12,"High","Standard"))) | H13: =IF(B13="","",IF(C13="CIOS→MIOS+OHOS","Brand Strategy + Medical + Training",IF(C13="CIOS→MIOS","Medical Strategy",IF(C13="CIOS→OHOS","Field Strategy / Training","CIOS Review")))) | I13: =IF(B13="","",IF(C13="CIOS→MIOS+OHOS","Update core message + objection module + segment guidance",IF(C13="CIOS→MIOS","Update message architecture + segment narrative",IF(C13="CIOS→OHOS","Update objection ladder + response card","Review")))) | J13: =IF(B13="","",IF(LEFT(D13,11)="Pulmonology","Sales + MSL","MSL-led"))

Sheet FieldGuidanceOutput
A1: Field Guidance Output
A3: Latest high-priority feedback | D3: MIOS implication
A4: =FieldIntelligenceInbox!L2 -> Pulmonologists are asking for a more direct connection between microbiology and fatigue / functioning. | D4: Update message hierarchy, proof sequence, and segment-specific belief bridge.
A6: Primary target population | B6: =FieldIntelligenceInbox!X2 -> Pulmonology / community | D6: OHOS implication
A7: Recommended route | B7: =FieldIntelligenceInbox!W2 -> CIOS→MIOS+OHOS | D7: Refine objection modules and response cards for the affected segment.
A8: Escalation level | B8: =MessageUpdateRouter!G4 -> Urgent
A9: Recommended owner | B9: =MessageUpdateRouter!H4 -> Brand Strategy + Medical + Training | D9: Sales / MSL implication
D10: Deploy differentiated talk tracks by specialty and subspecialty; monitor recurrence in next cycle.
A11: Updated field direction
A12: 1. Anchor the discussion in the segment's dominant decision driver.
A13: 2. Bridge evidence to the clinical endpoint that the segment finds meaningful.
A14: 3. Use the objection ladder only after the segment-specific framing is established.
A15: 4. Escalate recurring objections with high signal scores into OHOS within the same review cycle.

Sheet SalesGuidance
A1: Segment | B1: What to lead with | C1: What to avoid | D1: Proof asset to use | E1: Call objective | F1: Escalate if...
A2: Pulmonology / community | B2: Symptoms, function, simpler patient identification | C2: Opening with endpoint jargon alone | D2: Practical patient-fit aid | E2: Create confidence in candidate identification | F2: same objection appears across 3+ accounts
A3: Pulmonology / NTM-focused | B3: Disease control linked to patient meaning | C3: Oversimplifying evidence depth | D3: Mechanistic bridge + outcomes detail | E3: Strengthen belief that endpoint matters clinically | F3: clinical skepticism intensifies
A4: Infectious Disease / academic | B4: Evidence depth and differentiation | C4: Over-indexing on broad symptom language | D4: Evidence hierarchy summary | E4: Defend scientific distinctiveness | F4: comparative objection persists

Sheet MSLGuidance
A1: Segment | B1: Scientific angle | C1: Core bridge | D1: Likely challenge | E1: MSL response mode | F1: Evidence follow-up needed
A2: Pulmonology / NTM-focused | B2: Microbiology to clinical meaning | C2: Disease control → symptom/function | D2: Endpoint clinical relevance | E2: Mechanism + evidence bridge | F2: Yes
A3: Infectious Disease / academic | B3: Comparative evidence architecture | C3: Endpoint rigor → treatment confidence | D3: Alternative options easier to explain | E3: Structured scientific differentiation | F3: Yes
A4: Pulmonology / general | B4: Patient identification and referral logic | C4: Candidate clarity → treatment confidence | D4: Workflow burden | E4: Practical scientific framing | F4: Maybe

Sheet DeploymentTracker
A1: Closed-Loop Deployment Tracker
A3: DeploymentID | B3: FeedbackID | C3: Brand | D3: Segment | E3: Account | F3: FieldTeam | G3: RecommendedOutput | H3: DeploymentDate | I3: DeploymentType | J3: MessageVersion | K3: OHOSModuleVersion | L3: MIOSUpdateFlag | M3: Owner | N3: Status | O3: ReviewDate | P3: ObservationWindow_Days | Q3: PreObjectionRate | R3: PostObjectionRate | S3: PreAccessFriction | T3: PostAccessFriction | U3: PreEngagementScore | V3: PostEngagementScore | W3: ObjectionChange | X3: AccessFrictionChange | Y3: EngagementChange | Z3: NetFieldImprovement | AA3: EscalateBackToCIOS
A4: DEP-001 | B4: FB-001 | C4: ARIKAYCE | D4: Pulmonology / community | E4: Community Pulm Account A | F4: Sales + MSL | G4: Update core message + objection module + segment guidance | H4: 2026-03-20 | I4: Message + training | J4: MSG-v2 | K4: OHOS-v2 | L4: Yes | M4: Brand Strategy | N4: Live | O4: 2026-04-20 | P4: 30 | Q4: 0.6 | R4: 0.4 | S4: 0.5 | T4: 0.35 | U4: 3 | V4: 4 | W4: =R4-Q4 -> -0.2 | X4: =T4-S4 -> -0.15 | Y4: =V4-U4 -> 1 | Z4: =-(W4+X4)+Y4 -> 1.35 | AA4: =IF(Z4>0.4,"No","Yes") -> No
A5: DEP-002 | B5: FB-002 | C5: ARIKAYCE | D5: Infectious Disease / academic | E5: Academic ID Center | F5: MSL-led | G5: Update objection ladder + response card | H5: 2026-03-22 | I5: Scientific objection update | J5: MSG-v2 | K5: OHOS-v3 | L5: No | M5: Field Strategy | N5: Live | O5: 2026-04-22 | P5: 30 | Q5: 0.55 | R5: 0.48 | S5: 0.3 | T5: 0.28 | U5: 3.2 | V5: 3.8 | W5: =R5-Q5 -> -0.07 | X5: =T5-S5 -> -0.02 | Y5: =V5-U5 -> 0.6 | Z5: =-(W5+X5)+Y5 -> 0.69 | AA5: =IF(Z5>0.4,"No","Yes") -> No
A6: DEP-003 | B6: FB-003 | C6: ARIKAYCE | D6: Pulmonology / general | E6: General Pulm Network B | F6: Sales + MSL | G6: Update message architecture + segment narrative | H6: 2026-03-25 | I6: Message simplification | J6: MSG-v3 | K6: OHOS-v3 | L6: Yes | M6: Medical Strategy | N6: Planned | O6: 2026-04-25 | P6: 30 | Q6: 0.5 | R6: 0.5 | S6: 0.65 | T6: 0.65 | U6: 2.8 | V6: 2.8 | W6: =R6-Q6 -> 0 | X6: =T6-S6 -> 0 | Y6: =V6-U6 -> 0 | Z6: =-(W6+X6)+Y6 -> 0 | AA6: =IF(Z6>0.4,"No","Yes") -> Yes

Sheet SegmentOutcomeTracker
A1: Segment Outcome Tracker
A3: Segment | B3: Deployments | C3: AvgPreObjectionRate | D3: AvgPostObjectionRate | E3: AvgPreAccessFriction | F3: AvgPostAccessFriction | G3: AvgPreEngagement | H3: AvgPostEngagement | I3: AvgObjectionChange | J3: AvgAccessChange | K3: AvgEngagementChange | L3: AvgNetFieldImprovement | M3: Interpretation
A4: Pulmonology / community | B4: =COUNTIF(DeploymentTracker!D:D,A4) -> 1 | C4: =IF(B4=0,"",SUMIF(DeploymentTracker!D:D,A4,DeploymentTracker!Q:Q)/B4) -> 0.6 | D4: =IF(B4=0,"",SUMIF(DeploymentTracker!D:D,A4,DeploymentTracker!R:R)/B4) -> 0.4 | E4: =IF(B4=0,"",SUMIF(DeploymentTracker!D:D,A4,DeploymentTracker!S:S)/B4) -> 0.5 | F4: =IF(B4=0,"",SUMIF(DeploymentTracker!D:D,A4,DeploymentTracker!T:T)/B4) -> 0.35 | G4: =IF(B4=0,"",SUMIF(DeploymentTracker!D:D,A4,DeploymentTracker!U:U)/B4) -> 3 | H4: =IF(B4=0,"",SUMIF(DeploymentTracker!D:D,A4,DeploymentTracker!V:V)/B4) -> 4 | I4: =IF(B4=0,"",SUMIF(DeploymentTracker!D:D,A4,DeploymentTracker!W:W)/B4) -> -0.2 | J4: =IF(B4=0,"",SUMIF(DeploymentTracker!D:D,A4,DeploymentTracker!X:X)/B4) -> -0.15 | K4: =IF(B4=0,"",SUMIF(DeploymentTracker!D:D,A4,DeploymentTracker!Y:Y)/B4) -> 1 | L4: =IF(B4=0,"",SUMIF(DeploymentTracker!D:D,A4,DeploymentTracker!Z:Z)/B4) -> 1.35 | M4: =IF(L4="","",IF(L4>0.4,"Improving strongly",IF(L4>0.15,"Improving modestly","Limited movement"))) -> Improving strongly
A5: Infectious Disease / academic | B5: =COUNTIF(DeploymentTracker!D:D,A5) -> 1 | C5: =IF(B5=0,"",SUMIF(DeploymentTracker!D:D,A5,DeploymentTracker!Q:Q)/B5) -> 0.55 | D5: =IF(B5=0,"",SUMIF(DeploymentTracker!D:D,A5,DeploymentTracker!R:R)/B5) -> 0.48 | E5: =IF(B5=0,"",SUMIF(DeploymentTracker!D:D,A5,DeploymentTracker!S:S)/B5) -> 0.3 | F5: =IF(B5=0,"",SUMIF(DeploymentTracker!D:D,A5,DeploymentTracker!T:T)/B5) -> 0.28 | G5: =IF(B5=0,"",SUMIF(DeploymentTracker!D:D,A5,DeploymentTracker!U:U)/B5) -> 3.2 | H5: =IF(B5=0,"",SUMIF(DeploymentTracker!D:D,A5,DeploymentTracker!V:V)/B5) -> 3.8 | I5: =IF(B5=0,"",SUMIF(DeploymentTracker!D:D,A5,DeploymentTracker!W:W)/B5) -> -0.07 | J5: =IF(B5=0,"",SUMIF(DeploymentTracker!D:D,A5,DeploymentTracker!X:X)/B5) -> -0.02 | K5: =IF(B5=0,"",SUMIF(DeploymentTracker!D:D,A5,DeploymentTracker!Y:Y)/B5) -> 0.6 | L5: =IF(B5=0,"",SUMIF(DeploymentTracker!D:D,A5,DeploymentTracker!Z:Z)/B5) -> 0.69 | M5: =IF(L5="","",IF(L5>0.4,"Improving strongly",IF(L5>0.15,"Improving modestly","Limited movement"))) -> Improving strongly
A6: Pulmonology / general | B6: =COUNTIF(DeploymentTracker!D:D,A6) -> 1 | C6: =IF(B6=0,"",SUMIF(DeploymentTracker!D:D,A6,DeploymentTracker!Q:Q)/B6) -> 0.5 | D6: =IF(B6=0,"",SUMIF(DeploymentTracker!D:D,A6,DeploymentTracker!R:R)/B6) -> 0.5 | E6: =IF(B6=0,"",SUMIF(DeploymentTracker!D:D,A6,DeploymentTracker!S:S)/B6) -> 0.65 | F6: =IF(B6=0,"",SUMIF(DeploymentTracker!D:D,A6,DeploymentTracker!T:T)/B6) -> 0.65 | G6: =IF(B6=0,"",SUMIF(DeploymentTracker!D:D,A6,DeploymentTracker!U:U)/B6) -> 2.8 | H6: =IF(B6=0,"",SUMIF(DeploymentTracker!D:D,A6,DeploymentTracker!V:V)/B6) -> 2.8 | I6: =IF(B6=0,"",SUMIF(DeploymentTracker!D:D,A6,DeploymentTracker!W:W)/B6) -> 0 | J6: =IF(B6=0,"",SUMIF(DeploymentTracker!D:D,A6,DeploymentTracker!X:X)/B6) -> 0 | K6: =IF(B6=0,"",SUMIF(DeploymentTracker!D:D,A6,DeploymentTracker!Y:Y)/B6) -> 0 | L6: =IF(B6=0,"",SUMIF(DeploymentTracker!D:D,A6,DeploymentTracker!Z:Z)/B6) -> 0 | M6: =IF(L6="","",IF(L6>0.4,"Improving strongly",IF(L6>0.15,"Improving modestly","Limited movement"))) -> Limited movement

Sheet AccountFeedbackLoop
A1: Account Feedback Loop
A3: Account | B3: Segment | C3: LatestDeploymentID | D3: Status | E3: PreObjectionRate | F3: PostObjectionRate | G3: PreAccessFriction | H3: PostAccessFriction | I3: PreEngagement | J3: PostEngagement | K3: NetFieldImprovement | L3: RecommendedNextMove | M3: SendBackToMIOS | N3: SendBackToOHOS | O3: FollowUpOwner
A4: Community Pulm Account A | B4: Pulmonology / community | C4: =DeploymentTracker!A4 -> DEP-001 | D4: =DeploymentTracker!N4 -> Live | E4: =DeploymentTracker!Q4 -> 0.6 | F4: =DeploymentTracker!R4 -> 0.4 | G4: =DeploymentTracker!S4 -> 0.5 | H4: =DeploymentTracker!T4 -> 0.35 | I4: =DeploymentTracker!U4 -> 3 | J4: =DeploymentTracker!V4 -> 4 | K4: =DeploymentTracker!Z4 -> 1.35 | L4: =IF(K4="","",IF(K4>0.4,"Scale current approach",IF(K4>0.15,"Refine and re-test","Rework message and objection strategy"))) -> Scale current approach | M4: =IF(K4="","",IF(AND(K4<=0.15,E4-F4<0.1),"Yes","No")) -> No | N4: =IF(K4="","",IF(AND(K4<=0.15,G4-H4<0.05),"Yes","No")) -> No | O4: =IF(B4="","",IF(LEFT(B4,11)="Pulmonology","Sales + MSL","MSL-led")) -> Sales + MSL
A5: Academic ID Center | B5: Infectious Disease / academic | C5: =DeploymentTracker!A5 -> DEP-002 | D5: =DeploymentTracker!N5 -> Live | E5: =DeploymentTracker!Q5 -> 0.55 | F5: =DeploymentTracker!R5 -> 0.48 | G5: =DeploymentTracker!S5 -> 0.3 | H5: =DeploymentTracker!T5 -> 0.28 | I5: =DeploymentTracker!U5 -> 3.2 | J5: =DeploymentTracker!V5 -> 3.8 | K5: =DeploymentTracker!Z5 -> 0.69 | L5: =IF(K5="","",IF(K5>0.4,"Scale current approach",IF(K5>0.15,"Refine and re-test","Rework message and objection strategy"))) -> Scale current approach | M5: =IF(K5="","",IF(AND(K5<=0.15,E5-F5<0.1),"Yes","No")) -> No | N5: =IF(K5="","",IF(AND(K5<=0.15,G5-H5<0.05),"Yes","No")) -> No | O5: =IF(B5="","",IF(LEFT(B5,11)="Pulmonology","Sales + MSL","MSL-led")) -> MSL-led
A6: General Pulm Network B | B6: Pulmonology / general | C6: =DeploymentTracker!A6 -> DEP-003 | D6: =DeploymentTracker!N6 -> Planned | E6: =DeploymentTracker!Q6 -> 0.5 | F6: =DeploymentTracker!R6 -> 0.5 | G6: =DeploymentTracker!S6 -> 0.65 | H6: =DeploymentTracker!T6 -> 0.65 | I6: =DeploymentTracker!U6 -> 2.8 | J6: =DeploymentTracker!V6 -> 2.8 | K6: =DeploymentTracker!Z6 -> 0 | L6: =IF(K6="","",IF(K6>0.4,"Scale current approach",IF(K6>0.15,"Refine and re-test","Rework message and objection strategy"))) -> Rework message and objection strategy | M6: =IF(K6="","",IF(AND(K6<=0.15,E6-F6<0.1),"Yes","No")) -> Yes | N6: =IF(K6="","",IF(AND(K6<=0.15,G6-H6<0.05),"Yes","No")) -> Yes | O6: =IF(B6="","",IF(LEFT(B6,11)="Pulmonology","Sales + MSL","MSL-led")) -> Sales + MSL

Sheet ClosedLoopDashboard
A1: Closed-Loop Deployment Dashboard
A3: Live deployments | B3: =COUNTIF(DeploymentTracker!N:N,"Live") -> 2 | D3: System reading
A4: Planned deployments | B4: =COUNTIF(DeploymentTracker!N:N,"Planned") -> 1 | D4: =IF(B5>0.25,"Deployed updates are reducing friction in at least part of the field.","Field changes are not yet producing strong movement.") -> Deployed updates are reducing friction in at least part of the field.
A5: Average net field improvement | B5: =AVERAGE(DeploymentTracker!Z:Z) -> 0.68
A6: Accounts to send back to MIOS | B6: =COUNTIF(AccountFeedbackLoop!M:M,"Yes") -> 1 | D6: What to do next
A7: Accounts to send back to OHOS | B7: =COUNTIF(AccountFeedbackLoop!N:N,"Yes") -> 1 | D7: =IF(B6+B7>0,"Re-route weak-performing accounts to MIOS/OHOS review this cycle.","Continue scaled deployment and monitor repeat objections.") -> Re-route weak-performing accounts to MIOS/OHOS review this cycle.
A8: Segments improving strongly | B8: =COUNTIF(SegmentOutcomeTracker!M:M,"Improving strongly") -> 2
A10: Segment | B10: Avg Net Improvement | C10: Interpretation
A11: =SegmentOutcomeTracker!A4 -> Pulmonology / community | B11: =SegmentOutcomeTracker!L4 -> 1.35 | C11: =SegmentOutcomeTracker!M4 -> Improving strongly
A12: =SegmentOutcomeTracker!A5 -> Infectious Disease / academic | B12: =SegmentOutcomeTracker!L5 -> 0.69 | C12: =SegmentOutcomeTracker!M5 -> Improving strongly
A13: =SegmentOutcomeTracker!A6 -> Pulmonology / general | B13: =SegmentOutcomeTracker!L6 -> 0 | C13: =SegmentOutcomeTracker!M6 -> Limited movement
A16: Account | B16: Next Move | C16: Back to MIOS | D16: Back to OHOS
A17: =AccountFeedbackLoop!A4 -> Community Pulm Account A | B17: =AccountFeedbackLoop!L4 -> Scale current approach | C17: =AccountFeedbackLoop!M4 -> No | D17: =AccountFeedbackLoop!N4 -> No
A18: =AccountFeedbackLoop!A5 -> Academic ID Center | B18: =AccountFeedbackLoop!L5 -> Scale current approach | C18: =AccountFeedbackLoop!M5 -> No | D18: =AccountFeedbackLoop!N5 -> No
A19: =AccountFeedbackLoop!A6 -> General Pulm Network B | B19: =AccountFeedbackLoop!L6 -> Rework message and objection strategy | C19: =AccountFeedbackLoop!M6 -> Yes | D19: =AccountFeedbackLoop!N6 -> Yes

Sheet DeploymentInstructions
A1: Closed-Loop Deployment Instructions
A3: 1. Add new deployed changes to DeploymentTracker after message or objection updates go live.
A4: 2. Record pre- and post-deployment objection rate, access friction, and engagement score by account.
A5: 3. Review SegmentOutcomeTracker to see whether the updated message is working by specialty/subspecialty.
A6: 4. Review AccountFeedbackLoop to identify where the update should be sent back to MIOS or OHOS.
A7: 5. Use ClosedLoopDashboard as the leadership summary to show whether field change is reducing friction.
A8: 6. Architectural rule: CIOS detects and scores change; MIOS updates message architecture; OHOS updates objection response; field teams execute and measure.

Sheet SourceMonitorConfig
A1: Automation Layer - Source Monitor Configuration
A3: SourceID | B3: SourceType | C3: SourceName | D3: CoverageFocus | E3: MonitorFrequency | F3: TriggerPattern | G3: ExpectedSignalType | H3: DefaultBrand | I3: DefaultRoute | J3: Priority | K3: Active
A4: SRC-001 | B4: Literature | C4: PubMed | D4: Clinical / medical evidence | E4: Weekly | F4: new trial|meta-analysis|safety|guideline | G4: Clinical | H4: ARIKAYCE | I4: CIOS→MIOS | J4: 1 | K4: Yes
A5: SRC-002 | B5: Trials | C5: ClinicalTrials.gov | D5: Trial status and readouts | E5: Weekly | F5: recruiting complete|interim|primary completion|results posted | G5: Clinical | H5: ARIKAYCE | I5: CIOS | J5: 1 | K5: Yes
A6: SRC-003 | B6: Conference | C6: Medical congress abstracts | D6: Abstracts and presentations | E6: Weekly | F6: late-breaker|abstract|poster|oral presentation | G6: Clinical perception | H6: ARIKAYCE | I6: CIOS→MIOS | J6: 2 | K6: Yes
A7: SRC-004 | B7: Commercial | C7: Press releases / earnings / payer bulletins | D7: Market access and competition | E7: Weekly | F7: coverage|launch|label|guidance|commercial update | G7: Commercial | H7: ARIKAYCE | I7: CIOS→OHOS | J7: 2 | K7: Yes
A8: SRC-005 | B8: Field | C8: MSL / sales / KOL notes | D8: Field resistance and adoption barriers | E8: Weekly | F8: objection recurring|workflow|patient fit|comparative challenge | G8: Field intelligence | H8: ARIKAYCE | I8: CIOS→MIOS+OHOS | J8: 1 | K8: Yes

Sheet CandidateSignalQueue
A1: Candidate Signal Queue
A3: CandidateID | B3: DateDetected | C3: SourceID | D3: SourceName | E3: Brand | F3: RawSourceType | G3: Headline | H3: RawObservation | I3: ProposedSignalCategory | J3: ProposedDirection | K3: Urgency_1to5 | L3: Credibility_1to5 | M3: Frequency_1to5 | N3: PotentialImpact_1to5 | O3: AutomationPriorityScore | P3: SuggestedRoute | Q3: TargetSegment | R3: AnalystStatus | S3: AnalystDecision | T3: ValidationNotes | U3: ValidatedSignalID
A4: CS-001 | B4: 2026-03-13 | C4: SRC-001 | D4: PubMed | E4: ARIKAYCE | F4: Literature | G4: New publication emphasizes patient-relevant outcomes linkage | H4: A new publication appears to strengthen the bridge between microbiology and function. | I4: Clinical evidence | J4: Positive | K4: 4 | L4: 5 | M4: 2 | N4: 4 | O4: =SUM(K4:N4) -> 15 | P4: CIOS→MIOS | Q4: Pulmonology / NTM-focused | R4: Queued
A5: CS-002 | B5: 2026-03-13 | C5: SRC-005 | D5: Field notes | E5: ARIKAYCE | F5: Field | G5: Community pulmonologists still unclear on patient-fit | H5: Multiple accounts continue to ask for a simpler identification and referral story. | I5: Field intelligence | J5: Negative | K5: 4 | L5: 4 | M5: 4 | N5: 4 | O5: =SUM(K5:N5) -> 16 | P5: CIOS→MIOS+OHOS | Q5: Pulmonology / community | R5: Queued
A6: CS-003 | B6: 2026-03-13 | C6: SRC-004 | D6: Payer bulletin | E6: ARIKAYCE | F6: Commercial | G6: Coverage update may lower access friction in selected plans | H6: Emerging coverage shift could reduce reimbursement obstacles in target accounts. | I6: Access / commercial | J6: Positive | K6: 3 | L6: 4 | M6: 2 | N6: 5 | O6: =SUM(K6:N6) -> 14 | P6: CIOS→OHOS | Q6: Pulmonology / general | R6: Queued

Sheet SignalNormalization
A1: Signal Normalization Workbench
A3: CandidateID | B3: Brand | C3: Headline | D3: NormalizedSignalDescription | E3: SignalType | F3: Direction | G3: StrengthScore_1to5 | H3: ReliabilityScore_1to5 | I3: LikelihoodRatio | J3: SuggestedLinkedSystem | K3: TargetPopulation | L3: ProposedOwner | M3: ReadyForRegister
A4: =CandidateSignalQueue!A4 -> CS-001 | B4: =CandidateSignalQueue!E4 -> ARIKAYCE | C4: =CandidateSignalQueue!G4 -> New publication emphasizes patient-relevant outcomes linkage | D4: =IF(A4="","",CandidateSignalQueue!H4) -> A new publication appears to strengthen the bridge between microbiology and function. | E4: =IF(A4="","",CandidateSignalQueue!I4) -> Clinical evidence | F4: =IF(A4="","",CandidateSignalQueue!J4) -> Positive | G4: =IF(A4="","",ROUND(CandidateSignalQueue!N4/1,0)) -> 4 | H4: =IF(A4="","",ROUND(CandidateSignalQueue!L4/1,0)) -> 5 | I4: =IF(A4="","",IF(F4="Positive",1+(G4*0.08),1-(G4*0.08))) -> 1.32 | J4: =IF(A4="","",CandidateSignalQueue!P4) -> CIOS→MIOS | K4: =IF(A4="","",CandidateSignalQueue!Q4) -> Pulmonology / NTM-focused | L4: =IF(A4="","",IF(J4="CIOS→MIOS+OHOS","Brand Strategy + Medical + Training",IF(J4="CIOS→MIOS","Medical Strategy",IF(J4="CIOS→OHOS","Field Strategy / Training","CIOS Review")))) -> Medical Strategy | M4: =IF(A4="","",IF(CandidateSignalQueue!S4="Validate","Yes","No")) -> No
A5: =CandidateSignalQueue!A5 -> CS-002 | B5: =CandidateSignalQueue!E5 -> ARIKAYCE | C5: =CandidateSignalQueue!G5 -> Community pulmonologists still unclear on patient-fit | D5: =IF(A5="","",CandidateSignalQueue!H5) -> Multiple accounts continue to ask for a simpler identification and referral story. | E5: =IF(A5="","",CandidateSignalQueue!I5) -> Field intelligence | F5: =IF(A5="","",CandidateSignalQueue!J5) -> Negative | G5: =IF(A5="","",ROUND(CandidateSignalQueue!N5/1,0)) -> 4 | H5: =IF(A5="","",ROUND(CandidateSignalQueue!L5/1,0)) -> 4 | I5: =IF(A5="","",IF(F5="Positive",1+(G5*0.08),1-(G5*0.08))) -> 0.68 | J5: =IF(A5="","",CandidateSignalQueue!P5) -> CIOS→MIOS+OHOS | K5: =IF(A5="","",CandidateSignalQueue!Q5) -> Pulmonology / community | L5: =IF(A5="","",IF(J5="CIOS→MIOS+OHOS","Brand Strategy + Medical + Training",IF(J5="CIOS→MIOS","Medical Strategy",IF(J5="CIOS→OHOS","Field Strategy / Training","CIOS Review")))) -> Brand Strategy + Medical + Training | M5: =IF(A5="","",IF(CandidateSignalQueue!S5="Validate","Yes","No")) -> No
A6: =CandidateSignalQueue!A6 -> CS-003 | B6: =CandidateSignalQueue!E6 -> ARIKAYCE | C6: =CandidateSignalQueue!G6 -> Coverage update may lower access friction in selected plans | D6: =IF(A6="","",CandidateSignalQueue!H6) -> Emerging coverage shift could reduce reimbursement obstacles in target accounts. | E6: =IF(A6="","",CandidateSignalQueue!I6) -> Access / commercial | F6: =IF(A6="","",CandidateSignalQueue!J6) -> Positive | G6: =IF(A6="","",ROUND(CandidateSignalQueue!N6/1,0)) -> 5 | H6: =IF(A6="","",ROUND(CandidateSignalQueue!L6/1,0)) -> 4 | I6: =IF(A6="","",IF(F6="Positive",1+(G6*0.08),1-(G6*0.08))) -> 1.4 | J6: =IF(A6="","",CandidateSignalQueue!P6) -> CIOS→OHOS | K6: =IF(A6="","",CandidateSignalQueue!Q6) -> Pulmonology / general | L6: =IF(A6="","",IF(J6="CIOS→MIOS+OHOS","Brand Strategy + Medical + Training",IF(J6="CIOS→MIOS","Medical Strategy",IF(J6="CIOS→OHOS","Field Strategy / Training","CIOS Review")))) -> Field Strategy / Training | M6: =IF(A6="","",IF(CandidateSignalQueue!S6="Validate","Yes","No")) -> No
A7: =CandidateSignalQueue!A7 -> 0 | B7: =CandidateSignalQueue!E7 -> 0 | C7: =CandidateSignalQueue!G7 -> 0 | D7: =IF(A7="","",CandidateSignalQueue!H7) | E7: =IF(A7="","",CandidateSignalQueue!I7) | F7: =IF(A7="","",CandidateSignalQueue!J7) | G7: =IF(A7="","",ROUND(CandidateSignalQueue!N7/1,0)) | H7: =IF(A7="","",ROUND(CandidateSignalQueue!L7/1,0)) | I7: =IF(A7="","",IF(F7="Positive",1+(G7*0.08),1-(G7*0.08))) | J7: =IF(A7="","",CandidateSignalQueue!P7) | K7: =IF(A7="","",CandidateSignalQueue!Q7) | L7: =IF(A7="","",IF(J7="CIOS→MIOS+OHOS","Brand Strategy + Medical + Training",IF(J7="CIOS→MIOS","Medical Strategy",IF(J7="CIOS→OHOS","Field Strategy / Training","CIOS Review")))) | M7: =IF(A7="","",IF(CandidateSignalQueue!S7="Validate","Yes","No"))
A8: =CandidateSignalQueue!A8 -> 0 | B8: =CandidateSignalQueue!E8 -> 0 | C8: =CandidateSignalQueue!G8 -> 0 | D8: =IF(A8="","",CandidateSignalQueue!H8) | E8: =IF(A8="","",CandidateSignalQueue!I8) | F8: =IF(A8="","",CandidateSignalQueue!J8) | G8: =IF(A8="","",ROUND(CandidateSignalQueue!N8/1,0)) | H8: =IF(A8="","",ROUND(CandidateSignalQueue!L8/1,0)) | I8: =IF(A8="","",IF(F8="Positive",1+(G8*0.08),1-(G8*0.08))) | J8: =IF(A8="","",CandidateSignalQueue!P8) | K8: =IF(A8="","",CandidateSignalQueue!Q8) | L8: =IF(A8="","",IF(J8="CIOS→MIOS+OHOS","Brand Strategy + Medical + Training",IF(J8="CIOS→MIOS","Medical Strategy",IF(J8="CIOS→OHOS","Field Strategy / Training","CIOS Review")))) | M8: =IF(A8="","",IF(CandidateSignalQueue!S8="Validate","Yes","No"))
A9: =CandidateSignalQueue!A9 -> 0 | B9: =CandidateSignalQueue!E9 -> 0 | C9: =CandidateSignalQueue!G9 -> 0 | D9: =IF(A9="","",CandidateSignalQueue!H9) | E9: =IF(A9="","",CandidateSignalQueue!I9) | F9: =IF(A9="","",CandidateSignalQueue!J9) | G9: =IF(A9="","",ROUND(CandidateSignalQueue!N9/1,0)) | H9: =IF(A9="","",ROUND(CandidateSignalQueue!L9/1,0)) | I9: =IF(A9="","",IF(F9="Positive",1+(G9*0.08),1-(G9*0.08))) | J9: =IF(A9="","",CandidateSignalQueue!P9) | K9: =IF(A9="","",CandidateSignalQueue!Q9) | L9: =IF(A9="","",IF(J9="CIOS→MIOS+OHOS","Brand Strategy + Medical + Training",IF(J9="CIOS→MIOS","Medical Strategy",IF(J9="CIOS→OHOS","Field Strategy / Training","CIOS Review")))) | M9: =IF(A9="","",IF(CandidateSignalQueue!S9="Validate","Yes","No"))
A10: =CandidateSignalQueue!A10 -> 0 | B10: =CandidateSignalQueue!E10 -> 0 | C10: =CandidateSignalQueue!G10 -> 0 | D10: =IF(A10="","",CandidateSignalQueue!H10) | E10: =IF(A10="","",CandidateSignalQueue!I10) | F10: =IF(A10="","",CandidateSignalQueue!J10) | G10: =IF(A10="","",ROUND(CandidateSignalQueue!N10/1,0)) | H10: =IF(A10="","",ROUND(CandidateSignalQueue!L10/1,0)) | I10: =IF(A10="","",IF(F10="Positive",1+(G10*0.08),1-(G10*0.08))) | J10: =IF(A10="","",CandidateSignalQueue!P10) | K10: =IF(A10="","",CandidateSignalQueue!Q10) | L10: =IF(A10="","",IF(J10="CIOS→MIOS+OHOS","Brand Strategy + Medical + Training",IF(J10="CIOS→MIOS","Medical Strategy",IF(J10="CIOS→OHOS","Field Strategy / Training","CIOS Review")))) | M10: =IF(A10="","",IF(CandidateSignalQueue!S10="Validate","Yes","No"))
A11: =CandidateSignalQueue!A11 -> 0 | B11: =CandidateSignalQueue!E11 -> 0 | C11: =CandidateSignalQueue!G11 -> 0 | D11: =IF(A11="","",CandidateSignalQueue!H11) | E11: =IF(A11="","",CandidateSignalQueue!I11) | F11: =IF(A11="","",CandidateSignalQueue!J11) | G11: =IF(A11="","",ROUND(CandidateSignalQueue!N11/1,0)) | H11: =IF(A11="","",ROUND(CandidateSignalQueue!L11/1,0)) | I11: =IF(A11="","",IF(F11="Positive",1+(G11*0.08),1-(G11*0.08))) | J11: =IF(A11="","",CandidateSignalQueue!P11) | K11: =IF(A11="","",CandidateSignalQueue!Q11) | L11: =IF(A11="","",IF(J11="CIOS→MIOS+OHOS","Brand Strategy + Medical + Training",IF(J11="CIOS→MIOS","Medical Strategy",IF(J11="CIOS→OHOS","Field Strategy / Training","CIOS Review")))) | M11: =IF(A11="","",IF(CandidateSignalQueue!S11="Validate","Yes","No"))
A12: =CandidateSignalQueue!A12 -> 0 | B12: =CandidateSignalQueue!E12 -> 0 | C12: =CandidateSignalQueue!G12 -> 0 | D12: =IF(A12="","",CandidateSignalQueue!H12) | E12: =IF(A12="","",CandidateSignalQueue!I12) | F12: =IF(A12="","",CandidateSignalQueue!J12) | G12: =IF(A12="","",ROUND(CandidateSignalQueue!N12/1,0)) | H12: =IF(A12="","",ROUND(CandidateSignalQueue!L12/1,0)) | I12: =IF(A12="","",IF(F12="Positive",1+(G12*0.08),1-(G12*0.08))) | J12: =IF(A12="","",CandidateSignalQueue!P12) | K12: =IF(A12="","",CandidateSignalQueue!Q12) | L12: =IF(A12="","",IF(J12="CIOS→MIOS+OHOS","Brand Strategy + Medical + Training",IF(J12="CIOS→MIOS","Medical Strategy",IF(J12="CIOS→OHOS","Field Strategy / Training","CIOS Review")))) | M12: =IF(A12="","",IF(CandidateSignalQueue!S12="Validate","Yes","No"))
A13: =CandidateSignalQueue!A13 -> 0 | B13: =CandidateSignalQueue!E13 -> 0 | C13: =CandidateSignalQueue!G13 -> 0 | D13: =IF(A13="","",CandidateSignalQueue!H13) | E13: =IF(A13="","",CandidateSignalQueue!I13) | F13: =IF(A13="","",CandidateSignalQueue!J13) | G13: =IF(A13="","",ROUND(CandidateSignalQueue!N13/1,0)) | H13: =IF(A13="","",ROUND(CandidateSignalQueue!L13/1,0)) | I13: =IF(A13="","",IF(F13="Positive",1+(G13*0.08),1-(G13*0.08))) | J13: =IF(A13="","",CandidateSignalQueue!P13) | K13: =IF(A13="","",CandidateSignalQueue!Q13) | L13: =IF(A13="","",IF(J13="CIOS→MIOS+OHOS","Brand Strategy + Medical + Training",IF(J13="CIOS→MIOS","Medical Strategy",IF(J13="CIOS→OHOS","Field Strategy / Training","CIOS Review")))) | M13: =IF(A13="","",IF(CandidateSignalQueue!S13="Validate","Yes","No"))

Sheet ValidationWorkbench
A1: Analyst Validation Workbench
A3: CandidateID | B3: Headline | C3: PriorityScore | D3: SuggestedRoute | E3: SignalType | F3: Direction | G3: LikelihoodRatio | H3: ReadyForRegister | I3: ValidationDecision | J3: RegisterSignalID | K3: SendToMIOS | L3: SendToOHOS | M3: Comments
A4: =SignalNormalization!A4 -> CS-001 | B4: =SignalNormalization!C4 -> New publication emphasizes patient-relevant outcomes linkage | C4: =CandidateSignalQueue!O4 -> 15 | D4: =SignalNormalization!J4 -> CIOS→MIOS | E4: =SignalNormalization!E4 -> Clinical evidence | F4: =SignalNormalization!F4 -> Positive | G4: =SignalNormalization!I4 -> 1.32 | H4: =SignalNormalization!M4 -> No | J4: =IF(I4="Approve","SIG-AUTO-"&TEXT(ROW()-3,"000"),"") | K4: =IF(I4="Approve",IF(OR(D4="CIOS→MIOS",D4="CIOS→MIOS+OHOS"),"Yes","No"),"") | L4: =IF(I4="Approve",IF(OR(D4="CIOS→OHOS",D4="CIOS→MIOS+OHOS"),"Yes","No"),"")
A5: =SignalNormalization!A5 -> CS-002 | B5: =SignalNormalization!C5 -> Community pulmonologists still unclear on patient-fit | C5: =CandidateSignalQueue!O5 -> 16 | D5: =SignalNormalization!J5 -> CIOS→MIOS+OHOS | E5: =SignalNormalization!E5 -> Field intelligence | F5: =SignalNormalization!F5 -> Negative | G5: =SignalNormalization!I5 -> 0.68 | H5: =SignalNormalization!M5 -> No | J5: =IF(I5="Approve","SIG-AUTO-"&TEXT(ROW()-3,"000"),"") | K5: =IF(I5="Approve",IF(OR(D5="CIOS→MIOS",D5="CIOS→MIOS+OHOS"),"Yes","No"),"") | L5: =IF(I5="Approve",IF(OR(D5="CIOS→OHOS",D5="CIOS→MIOS+OHOS"),"Yes","No"),"")
A6: =SignalNormalization!A6 -> CS-003 | B6: =SignalNormalization!C6 -> Coverage update may lower access friction in selected plans | C6: =CandidateSignalQueue!O6 -> 14 | D6: =SignalNormalization!J6 -> CIOS→OHOS | E6: =SignalNormalization!E6 -> Access / commercial | F6: =SignalNormalization!F6 -> Positive | G6: =SignalNormalization!I6 -> 1.4 | H6: =SignalNormalization!M6 -> No | J6: =IF(I6="Approve","SIG-AUTO-"&TEXT(ROW()-3,"000"),"") | K6: =IF(I6="Approve",IF(OR(D6="CIOS→MIOS",D6="CIOS→MIOS+OHOS"),"Yes","No"),"") | L6: =IF(I6="Approve",IF(OR(D6="CIOS→OHOS",D6="CIOS→MIOS+OHOS"),"Yes","No"),"")
A7: =SignalNormalization!A7 -> 0 | B7: =SignalNormalization!C7 -> 0 | C7: =CandidateSignalQueue!O7 -> 0 | D7: =SignalNormalization!J7 | E7: =SignalNormalization!E7 | F7: =SignalNormalization!F7 | G7: =SignalNormalization!I7 | H7: =SignalNormalization!M7 | J7: =IF(I7="Approve","SIG-AUTO-"&TEXT(ROW()-3,"000"),"") | K7: =IF(I7="Approve",IF(OR(D7="CIOS→MIOS",D7="CIOS→MIOS+OHOS"),"Yes","No"),"") | L7: =IF(I7="Approve",IF(OR(D7="CIOS→OHOS",D7="CIOS→MIOS+OHOS"),"Yes","No"),"")
A8: =SignalNormalization!A8 -> 0 | B8: =SignalNormalization!C8 -> 0 | C8: =CandidateSignalQueue!O8 -> 0 | D8: =SignalNormalization!J8 | E8: =SignalNormalization!E8 | F8: =SignalNormalization!F8 | G8: =SignalNormalization!I8 | H8: =SignalNormalization!M8 | J8: =IF(I8="Approve","SIG-AUTO-"&TEXT(ROW()-3,"000"),"") | K8: =IF(I8="Approve",IF(OR(D8="CIOS→MIOS",D8="CIOS→MIOS+OHOS"),"Yes","No"),"") | L8: =IF(I8="Approve",IF(OR(D8="CIOS→OHOS",D8="CIOS→MIOS+OHOS"),"Yes","No"),"")
A9: =SignalNormalization!A9 -> 0 | B9: =SignalNormalization!C9 -> 0 | C9: =CandidateSignalQueue!O9 -> 0 | D9: =SignalNormalization!J9 | E9: =SignalNormalization!E9 | F9: =SignalNormalization!F9 | G9: =SignalNormalization!I9 | H9: =SignalNormalization!M9 | J9: =IF(I9="Approve","SIG-AUTO-"&TEXT(ROW()-3,"000"),"") | K9: =IF(I9="Approve",IF(OR(D9="CIOS→MIOS",D9="CIOS→MIOS+OHOS"),"Yes","No"),"") | L9: =IF(I9="Approve",IF(OR(D9="CIOS→OHOS",D9="CIOS→MIOS+OHOS"),"Yes","No"),"")
A10: =SignalNormalization!A10 -> 0 | B10: =SignalNormalization!C10 -> 0 | C10: =CandidateSignalQueue!O10 -> 0 | D10: =SignalNormalization!J10 | E10: =SignalNormalization!E10 | F10: =SignalNormalization!F10 | G10: =SignalNormalization!I10 | H10: =SignalNormalization!M10 | J10: =IF(I10="Approve","SIG-AUTO-"&TEXT(ROW()-3,"000"),"") | K10: =IF(I10="Approve",IF(OR(D10="CIOS→MIOS",D10="CIOS→MIOS+OHOS"),"Yes","No"),"") | L10: =IF(I10="Approve",IF(OR(D10="CIOS→OHOS",D10="CIOS→MIOS+OHOS"),"Yes","No"),"")
A11: =SignalNormalization!A11 -> 0 | B11: =SignalNormalization!C11 -> 0 | C11: =CandidateSignalQueue!O11 -> 0 | D11: =SignalNormalization!J11 | E11: =SignalNormalization!E11 | F11: =SignalNormalization!F11 | G11: =SignalNormalization!I11 | H11: =SignalNormalization!M11 | J11: =IF(I11="Approve","SIG-AUTO-"&TEXT(ROW()-3,"000"),"") | K11: =IF(I11="Approve",IF(OR(D11="CIOS→MIOS",D11="CIOS→MIOS+OHOS"),"Yes","No"),"") | L11: =IF(I11="Approve",IF(OR(D11="CIOS→OHOS",D11="CIOS→MIOS+OHOS"),"Yes","No"),"")
A12: =SignalNormalization!A12 -> 0 | B12: =SignalNormalization!C12 -> 0 | C12: =CandidateSignalQueue!O12 -> 0 | D12: =SignalNormalization!J12 | E12: =SignalNormalization!E12 | F12: =SignalNormalization!F12 | G12: =SignalNormalization!I12 | H12: =SignalNormalization!M12 | J12: =IF(I12="Approve","SIG-AUTO-"&TEXT(ROW()-3,"000"),"") | K12: =IF(I12="Approve",IF(OR(D12="CIOS→MIOS",D12="CIOS→MIOS+OHOS"),"Yes","No"),"") | L12: =IF(I12="Approve",IF(OR(D12="CIOS→OHOS",D12="CIOS→MIOS+OHOS"),"Yes","No"),"")
A13: =SignalNormalization!A13 -> 0 | B13: =SignalNormalization!C13 -> 0 | C13: =CandidateSignalQueue!O13 -> 0 | D13: =SignalNormalization!J13 | E13: =SignalNormalization!E13 | F13: =SignalNormalization!F13 | G13: =SignalNormalization!I13 | H13: =SignalNormalization!M13 | J13: =IF(I13="Approve","SIG-AUTO-"&TEXT(ROW()-3,"000"),"") | K13: =IF(I13="Approve",IF(OR(D13="CIOS→MIOS",D13="CIOS→MIOS+OHOS"),"Yes","No"),"") | L13: =IF(I13="Approve",IF(OR(D13="CIOS→OHOS",D13="CIOS→MIOS+OHOS"),"Yes","No"),"")

Sheet RegisterPush
A1: Validated Signal Register Push
A3: RegisterSignalID | B3: CandidateID | C3: Brand | D3: SignalDescription | E3: SignalType | F3: Direction | G3: StrengthScore | H3: ReliabilityScore | I3: LikelihoodRatio | J3: Route | K3: TargetPopulation | L3: MIOSFlag | M3: OHOSFlag | N3: ReadyForManualCopy
A4: =IF(ValidationWorkbench!I4="Approve",ValidationWorkbench!J4,"") | B4: =ValidationWorkbench!A4 -> CS-001 | C4: =SignalNormalization!B4 -> ARIKAYCE | D4: =SignalNormalization!D4 -> A new publication appears to strengthen the bridge between microbiology and function. | E4: =SignalNormalization!E4 -> Clinical evidence | F4: =SignalNormalization!F4 -> Positive | G4: =SignalNormalization!G4 -> 4 | H4: =SignalNormalization!H4 -> 5 | I4: =SignalNormalization!I4 -> 1.32 | J4: =SignalNormalization!J4 -> CIOS→MIOS | K4: =SignalNormalization!K4 -> Pulmonology / NTM-focused | L4: =ValidationWorkbench!K4 | M4: =ValidationWorkbench!L4 | N4: =IF(A4<>"","Yes","")
A5: =IF(ValidationWorkbench!I5="Approve",ValidationWorkbench!J5,"") | B5: =ValidationWorkbench!A5 -> CS-002 | C5: =SignalNormalization!B5 -> ARIKAYCE | D5: =SignalNormalization!D5 -> Multiple accounts continue to ask for a simpler identification and referral story. | E5: =SignalNormalization!E5 -> Field intelligence | F5: =SignalNormalization!F5 -> Negative | G5: =SignalNormalization!G5 -> 4 | H5: =SignalNormalization!H5 -> 4 | I5: =SignalNormalization!I5 -> 0.68 | J5: =SignalNormalization!J5 -> CIOS→MIOS+OHOS | K5: =SignalNormalization!K5 -> Pulmonology / community | L5: =ValidationWorkbench!K5 | M5: =ValidationWorkbench!L5 | N5: =IF(A5<>"","Yes","")
A6: =IF(ValidationWorkbench!I6="Approve",ValidationWorkbench!J6,"") | B6: =ValidationWorkbench!A6 -> CS-003 | C6: =SignalNormalization!B6 -> ARIKAYCE | D6: =SignalNormalization!D6 -> Emerging coverage shift could reduce reimbursement obstacles in target accounts. | E6: =SignalNormalization!E6 -> Access / commercial | F6: =SignalNormalization!F6 -> Positive | G6: =SignalNormalization!G6 -> 5 | H6: =SignalNormalization!H6 -> 4 | I6: =SignalNormalization!I6 -> 1.4 | J6: =SignalNormalization!J6 -> CIOS→OHOS | K6: =SignalNormalization!K6 -> Pulmonology / general | L6: =ValidationWorkbench!K6 | M6: =ValidationWorkbench!L6 | N6: =IF(A6<>"","Yes","")
A7: =IF(ValidationWorkbench!I7="Approve",ValidationWorkbench!J7,"") | B7: =ValidationWorkbench!A7 -> 0 | C7: =SignalNormalization!B7 -> 0 | D7: =SignalNormalization!D7 | E7: =SignalNormalization!E7 | F7: =SignalNormalization!F7 | G7: =SignalNormalization!G7 | H7: =SignalNormalization!H7 | I7: =SignalNormalization!I7 | J7: =SignalNormalization!J7 | K7: =SignalNormalization!K7 | L7: =ValidationWorkbench!K7 | M7: =ValidationWorkbench!L7 | N7: =IF(A7<>"","Yes","")
A8: =IF(ValidationWorkbench!I8="Approve",ValidationWorkbench!J8,"") | B8: =ValidationWorkbench!A8 -> 0 | C8: =SignalNormalization!B8 -> 0 | D8: =SignalNormalization!D8 | E8: =SignalNormalization!E8 | F8: =SignalNormalization!F8 | G8: =SignalNormalization!G8 | H8: =SignalNormalization!H8 | I8: =SignalNormalization!I8 | J8: =SignalNormalization!J8 | K8: =SignalNormalization!K8 | L8: =ValidationWorkbench!K8 | M8: =ValidationWorkbench!L8 | N8: =IF(A8<>"","Yes","")
A9: =IF(ValidationWorkbench!I9="Approve",ValidationWorkbench!J9,"") | B9: =ValidationWorkbench!A9 -> 0 | C9: =SignalNormalization!B9 -> 0 | D9: =SignalNormalization!D9 | E9: =SignalNormalization!E9 | F9: =SignalNormalization!F9 | G9: =SignalNormalization!G9 | H9: =SignalNormalization!H9 | I9: =SignalNormalization!I9 | J9: =SignalNormalization!J9 | K9: =SignalNormalization!K9 | L9: =ValidationWorkbench!K9 | M9: =ValidationWorkbench!L9 | N9: =IF(A9<>"","Yes","")
A10: =IF(ValidationWorkbench!I10="Approve",ValidationWorkbench!J10,"") | B10: =ValidationWorkbench!A10 -> 0 | C10: =SignalNormalization!B10 -> 0 | D10: =SignalNormalization!D10 | E10: =SignalNormalization!E10 | F10: =SignalNormalization!F10 | G10: =SignalNormalization!G10 | H10: =SignalNormalization!H10 | I10: =SignalNormalization!I10 | J10: =SignalNormalization!J10 | K10: =SignalNormalization!K10 | L10: =ValidationWorkbench!K10 | M10: =ValidationWorkbench!L10 | N10: =IF(A10<>"","Yes","")
A11: =IF(ValidationWorkbench!I11="Approve",ValidationWorkbench!J11,"") | B11: =ValidationWorkbench!A11 -> 0 | C11: =SignalNormalization!B11 -> 0 | D11: =SignalNormalization!D11 | E11: =SignalNormalization!E11 | F11: =SignalNormalization!F11 | G11: =SignalNormalization!G11 | H11: =SignalNormalization!H11 | I11: =SignalNormalization!I11 | J11: =SignalNormalization!J11 | K11: =SignalNormalization!K11 | L11: =ValidationWorkbench!K11 | M11: =ValidationWorkbench!L11 | N11: =IF(A11<>"","Yes","")
A12: =IF(ValidationWorkbench!I12="Approve",ValidationWorkbench!J12,"") | B12: =ValidationWorkbench!A12 -> 0 | C12: =SignalNormalization!B12 -> 0 | D12: =SignalNormalization!D12 | E12: =SignalNormalization!E12 | F12: =SignalNormalization!F12 | G12: =SignalNormalization!G12 | H12: =SignalNormalization!H12 | I12: =SignalNormalization!I12 | J12: =SignalNormalization!J12 | K12: =SignalNormalization!K12 | L12: =ValidationWorkbench!K12 | M12: =ValidationWorkbench!L12 | N12: =IF(A12<>"","Yes","")
A13: =IF(ValidationWorkbench!I13="Approve",ValidationWorkbench!J13,"") | B13: =ValidationWorkbench!A13 -> 0 | C13: =SignalNormalization!B13 -> 0 | D13: =SignalNormalization!D13 | E13: =SignalNormalization!E13 | F13: =SignalNormalization!F13 | G13: =SignalNormalization!G13 | H13: =SignalNormalization!H13 | I13: =SignalNormalization!I13 | J13: =SignalNormalization!J13 | K13: =SignalNormalization!K13 | L13: =ValidationWorkbench!K13 | M13: =ValidationWorkbench!L13 | N13: =IF(A13<>"","Yes","")

Sheet AutomationDashboard
A1: Automation Layer Dashboard
A3: Queued candidates | B3: =COUNTIF(CandidateSignalQueue!R:R,"Queued") -> 3 | D3: System reading
A4: In review | B4: =COUNTIF(CandidateSignalQueue!R:R,"In Review") -> 0 | D4: =IF(B5+B6>0,"Automation queue is being filtered through analyst review before register entry.","No review activity yet.") -> No review activity yet.
A5: Approved | B5: =COUNTIF(ValidationWorkbench!I:I,"Approve") -> 0
A6: Rejected | B6: =COUNTIF(ValidationWorkbench!I:I,"Reject") -> 0 | D6: Next action
A7: Escalated | B7: =COUNTIF(ValidationWorkbench!I:I,"Escalate") -> 0 | D7: =IF(B8>0,"Copy approved rows from RegisterPush into SignalRegister / MIOS / OHOS workflow.","Continue reviewing queued candidates.") -> Continue reviewing queued candidates.
A8: Ready for SignalRegister | B8: =COUNTIF(RegisterPush!N:N,"Yes") -> 0
A10: Top candidate | B10: Priority | C10: Route | D10: Analyst decision
A11: =CandidateSignalQueue!A4 -> CS-001 | B11: =CandidateSignalQueue!O4 -> 15 | C11: =CandidateSignalQueue!P4 -> CIOS→MIOS | D11: =ValidationWorkbench!I4 -> 0
A12: =CandidateSignalQueue!A5 -> CS-002 | B12: =CandidateSignalQueue!O5 -> 16 | C12: =CandidateSignalQueue!P5 -> CIOS→MIOS+OHOS | D12: =ValidationWorkbench!I5 -> 0
A13: =CandidateSignalQueue!A6 -> CS-003 | B13: =CandidateSignalQueue!O6 -> 14 | C13: =CandidateSignalQueue!P6 -> CIOS→OHOS | D13: =ValidationWorkbench!I6 -> 0
A14: =CandidateSignalQueue!A7 -> 0 | B14: =CandidateSignalQueue!O7 -> 0 | C14: =CandidateSignalQueue!P7 -> 0 | D14: =ValidationWorkbench!I7 -> 0
A15: =CandidateSignalQueue!A8 -> 0 | B15: =CandidateSignalQueue!O8 -> 0 | C15: =CandidateSignalQueue!P8 -> 0 | D15: =ValidationWorkbench!I8 -> 0

Sheet AutomationInstructions
A1: Automation Layer Instructions
A3: 1. Configure monitored sources in SourceMonitorConfig by source type, trigger patterns, and route.
A4: 2. Add machine-detected candidate observations into CandidateSignalQueue.
A5: 3. Use SignalNormalization to convert raw observations into structured signal fields.
A6: 4. Analyst reviews the normalized candidates in ValidationWorkbench and marks Approve / Reject / Escalate / Hold.
A7: 5. Approved candidates populate RegisterPush and can be copied into CIOS SignalRegister and routed to MIOS / OHOS.
A8: 6. Architectural rule: automation proposes candidate signals; humans validate before they affect the core engine.
A9: 7. This keeps CIOS deterministic while still allowing scalable signal intake.

Sheet Cockpit_Home
A1: CaseID | B1: StrategicQuestion | C1: OutcomeDefinition | D1: TimeHorizon | E1: CurrentProbability | F1: ConfidenceLevel | G1: LastUpdate
A2: =CaseHeader!B4 -> CASE-001 | B2: =CaseHeader!B5 -> Will the monitored brand move closer to target adoption given the current validated signal set? | C2: =CaseHeader!B6 -> Net probability that the target outcome becomes more likely after signal validation and actor-response translation. | D2: =CaseHeader!B7 -> 12 months | E2: =ProbabilityEngine!B9 -> 0.59946999 | F2: =ProbabilityEngine!B10 -> High | G2: =CaseHeader!B13 -> 46096
A4: V18 upgrade | B4: Actor-reaction layer inserted between signal structuring and core probability update.
A5: Pharma tuning | B5: Actor logic now adapts by specialty profile, payer environment, guideline leverage, competitor profile, and target-population keywords.
A6: V19 upgrade | B6: Specialty-specific actor sets now swap the active actor composition by therapeutic context while preserving the same probability engine.

Sheet CaseHeader
A1: CIOS V18 Case Header
A3: Field | B3: Value
A4: CaseID | B4: CASE-001
A5: StrategicQuestion | B5: Will the monitored brand move closer to target adoption given the current validated signal set?
A6: OutcomeDefinition | B6: Net probability that the target outcome becomes more likely after signal validation and actor-response translation.
A7: TimeHorizon | B7: 12 months
A8: PriorProbability | B8: 0.45
A9: CurrentProbability | B9: =ProbabilityEngine!B9 -> 0.59946999
A10: ConfidenceLevel | B10: =ProbabilityEngine!B10 -> High
A11: SignalCount | B11: =COUNTIF(SignalRegister!A4:A33,"<>") -> 30
A12: PrimaryBrand | B12: =IFERROR(INDEX(SignalRegister!C4:C33,MATCH(TRUE(),INDEX(SignalRegister!C4:C33<>"",0),0)),"") -> ARIKAYCE
A13: LastUpdate | B13: =TODAY() -> 46096
A14: TopSupportiveActor | B14: =ActorAggregation!B10 -> Academic KOLs
A15: TopConstrainingActor | B15: =ActorAggregation!B11 -> Competitor Counteraction
A16: PrimarySpecialtyProfile | B16: General
A17: PayerEnvironment | B17: Balanced
A18: GuidelineLeverage | B18: Medium
A19: CompetitorProfile | B19: Entrenched standard of care
A21: UpgradeNote | B21: V19 adds specialty-specific actor sets while preserving the V18 actor-reaction and probability architecture.
A22: ActiveActorSet | B22: =B16 -> General

Sheet SignalRegister
A1: CIOS V18 Signal Register
A3: SignalID | B3: CandidateID | C3: Brand | D3: SignalDescription | E3: SignalType | F3: Direction | G3: StrengthScore | H3: ReliabilityScore | I3: LikelihoodRatio | J3: Route | K3: TargetPopulation | L3: MIOSFlag | M3: OHOSFlag | N3: WeightedSignalScore | O3: ActorAdjustedImpact | P3: ActiveLikelihoodRatio | Q3: AbsoluteImpact
A4: =IF(RegisterPush!B4="","",IF(RegisterPush!A4<>"",RegisterPush!A4,RegisterPush!B4)) -> CS-001 | B4: =IF(RegisterPush!B4="","",RegisterPush!B4) -> CS-001 | C4: =IF(RegisterPush!B4="","",RegisterPush!C4) -> ARIKAYCE | D4: =IF(RegisterPush!B4="","",RegisterPush!D4) -> A new publication appears to strengthen the bridge between microbiology and function. | E4: =IF(RegisterPush!B4="","",RegisterPush!E4) -> Clinical evidence | F4: =IF(RegisterPush!B4="","",RegisterPush!F4) -> Positive | G4: =IF(RegisterPush!B4="","",RegisterPush!G4) -> 4 | H4: =IF(RegisterPush!B4="","",RegisterPush!H4) -> 5 | I4: =IF(RegisterPush!B4="","",RegisterPush!I4) -> 1.32 | J4: =IF(RegisterPush!B4="","",RegisterPush!J4) -> CIOS→MIOS | K4: =IF(RegisterPush!B4="","",RegisterPush!K4) -> Pulmonology / NTM-focused | L4: =IF(B4="","",IF(RegisterPush!L4<>"",RegisterPush!L4,IF(OR(J4="CIOS→MIOS",J4="CIOS→MIOS+OHOS"),"Yes","No"))) -> Yes | M4: =IF(B4="","",IF(RegisterPush!M4<>"",RegisterPush!M4,IF(OR(J4="CIOS→OHOS",J4="CIOS→MIOS+OHOS"),"Yes","No"))) -> No | N4: =IF(B4="","",G4*H4) -> 20 | O4: =IF(B4="","",ActorReactionMatrix!M4) -> 0.74808375 | P4: =IF(B4="",1,IF(I4="",1,I4)) -> 1.32 | Q4: =IF(B4="","",ABS(O4)) -> 0.74808375
A5: =IF(RegisterPush!B5="","",IF(RegisterPush!A5<>"",RegisterPush!A5,RegisterPush!B5)) -> CS-002 | B5: =IF(RegisterPush!B5="","",RegisterPush!B5) -> CS-002 | C5: =IF(RegisterPush!B5="","",RegisterPush!C5) -> ARIKAYCE | D5: =IF(RegisterPush!B5="","",RegisterPush!D5) -> Multiple accounts continue to ask for a simpler identification and referral story. | E5: =IF(RegisterPush!B5="","",RegisterPush!E5) -> Field intelligence | F5: =IF(RegisterPush!B5="","",RegisterPush!F5) -> Negative | G5: =IF(RegisterPush!B5="","",RegisterPush!G5) -> 4 | H5: =IF(RegisterPush!B5="","",RegisterPush!H5) -> 4 | I5: =IF(RegisterPush!B5="","",RegisterPush!I5) -> 0.68 | J5: =IF(RegisterPush!B5="","",RegisterPush!J5) -> CIOS→MIOS+OHOS | K5: =IF(RegisterPush!B5="","",RegisterPush!K5) -> Pulmonology / community | L5: =IF(B5="","",IF(RegisterPush!L5<>"",RegisterPush!L5,IF(OR(J5="CIOS→MIOS",J5="CIOS→MIOS+OHOS"),"Yes","No"))) -> Yes | M5: =IF(B5="","",IF(RegisterPush!M5<>"",RegisterPush!M5,IF(OR(J5="CIOS→OHOS",J5="CIOS→MIOS+OHOS"),"Yes","No"))) -> Yes | N5: =IF(B5="","",G5*H5) -> 16 | O5: =IF(B5="","",ActorReactionMatrix!M5) -> -0.67531251 | P5: =IF(B5="",1,IF(I5="",1,I5)) -> 0.68 | Q5: =IF(B5="","",ABS(O5)) -> 0.67531251
